Workbook

Sheet Analysis
B1: Stocks | C1: mean | D1: sd | E1: sharpe | F1: conf interv | G1: var | H1: beta | I1: alpha
B2: appl | C2: =appl!N3 -> 0.00083929393 | D2: =appl!N8 -> 0.016516124 | E2: =appl!N9 -> 0.050816641 | F2: =appl!N11 -> 0.00083276792 | G2: =appl!N7 -> 0.00027278234 | H2: =appl!M32 -> 0.90008643 | I2: =appl!M31 -> 0.00044039568
B3: appl_2 | C3: =appl_2!P5 -> -0.00057062742 | D3: =appl_2!P9 -> 0.083356206 | E3: =appl_2!P20 -> -0.0068456501 | F3: =appl_2!P18 -> 0.052962007 | G3: =appl_2!P10 -> 0.0069482571
B4: bidu | C4: =bidu!M3 -> 0.00089719644 | D4: =bidu!M8 -> 0.024940452 | E4: =bidu!M9 -> 0.035973543 | F4: =bidu!M11 -> 0.0012575353 | G4: =bidu!M7 -> 0.00062202616 | H4: =bidu!L32 -> 1.3122063 | I4: =bidu!L31 -> 0.00031565585
B5: cop | C5: =cop!M3 -> 0.00040281925 | D5: =cop!M8 -> 0.016763281 | E5: =cop!M9 -> 0.024029856 | F5: =cop!M11 -> 0.00084522998 | G5: =cop!M7 -> 0.0002810076 | H5: =cop!L32 -> 1.1685959 | I5: =cop!L31 -> -0.00011507642
B6: dis | C6: =dis!M3 -> 0.0008977099 | D6: =dis!M8 -> 0.01373353 | E6: =dis!M9 -> 0.065366289 | F6: =dis!M11 -> 0.00069246535 | G6: =dis!M7 -> 0.00018860985 | H6: =dis!L32 -> 1.1295707 | I6: =dis!L31 -> 0.00039710933
B7: dji | C7: =dji!M3 -> 0.00044317772 | D7: =dji!M8 -> 0.0091104385 | E7: =dji!M9 -> 0.048645048 | F7: =dji!M11 -> 0.00045936208 | G7: =dji!M7 -> 8.300009e-05
B8: goog | C8: =goog!M3 -> 0.00087825152 | D8: =goog!M8 -> 0.015998245 | E8: =goog!M9 -> 0.05489674 | F8: =goog!M11 -> 0.00080665571 | G8: =goog!M7 -> 0.00025594385 | H8: =goog!L32 -> 0.97271782 | I8: =goog!L31 -> 0.00044716465
B9: msft | C9: =msft!M3 -> 0.00074693549 | D9: =msft!M8 -> 0.014817916 | E9: =msft!M9 -> 0.050407592 | F9: =msft!M11 -> 0.00074714174 | G9: =msft!M7 -> 0.00021957065 | H9: =msft!L32 -> 1.0434897 | I9: =msft!L31 -> 0.00028448409
B10: tesla | C10: =tesla!M3 -> 0.0020281441 | D10: =tesla!M8 -> 0.034218048 | E10: =tesla!M9 -> 0.05927118 | F10: =tesla!M11 -> 0.0017253257 | G10: =tesla!M7 -> 0.0011708748 | H10: =tesla!L32 -> 1.239124 | I10: =tesla!L31 -> 0.0014789919
B11: ttm | C11: =ttm!M3 -> 0.00081483095 | D11: =ttm!M8 -> 0.024832681 | E11: =ttm!M9 -> 0.032812846 | F11: =ttm!M11 -> 0.0012521013 | G11: =ttm!M7 -> 0.00061666206 | H11: =ttm!L32 -> 1.4927608 | I11: =ttm!L31 -> 0.00015327263
B12: wfc | C12: =wfc!M3 -> 0.00062554756 | D12: =wfc!M8 -> 0.015646004 | E12: =wfc!M9 -> 0.039981298 | F12: =wfc!M11 -> 0.00078889518 | G12: =wfc!M7 -> 0.00024479745 | H12: =wfc!L32 -> 1.3397083 | I12: =wfc!L31 -> 3.1818693e-05 | Q12: {=MMULT(C32:C41,C19:L28)} -> #VALUE!
B13: xom | C13: =xom!O5 -> 0.00051131218 | D13: =xom!O9 -> 0.011975959 | E13: =xom!O20 -> 0.042694883 | F13: =xom!O18 -> 0.00060433037 | G13: =xom!O10 -> 0.0001434236 | H13: =xom!L47 -> 1.0151406 | I13: =xom!L46 -> 6.1424473e-05
C18: Column 1 | D18: Column 2 | E18: Column 3 | F18: Column 4 | G18: Column 5 | H18: Column 6 | I18: Column 7 | J18: Column 8 | K18: Column 9 | L18: Column 10 | P18: {=MMULT(B33:K33,C19:L28)} -> 0.00010870548 | Q18: 0.00018475589 | R18: 0.00012260607 | S18: 0.00014306766 | T18: 0.00013719369 | U18: 0.00010749104 | V18: 0.0007423307 | W18: 0.00018606707 | X18: 0.00013182185 | Y18: 8.261204e-05
B19: Column 1 | C19: =VARP('10Stocks_'!$A$1518:$A$3028) -> 0.00027260181 | D19: =C20 -> 0.00014020363 | E19: =C21 -> 8.6396286e-05 | F19: =C22 -> 7.9833364e-05 | G19: =C23 -> 0.00010334608 | H19: =C24 -> 9.1197689e-05 | I19: =C25 -> 0.00012384515 | J19: =C26 -> 0.00012624627 | K19: =C27 -> 9.953054e-05 | L19: =C28 -> 6.7677521e-05 | N19: 0.00083929393
B20: Column 2 | C20: 0.00014020363 | D20: =VARP('10Stocks_'!$B$1518:$B$3028) -> 0.00062161449 | E20: =D21 -> 0.00013579362 | F20: =D22 -> 0.00013076058 | G20: =D23 -> 0.00017083205 | H20: =D24 -> 0.0001261591 | I20: =D25 -> 0.00021329347 | J20: =D26 -> 0.00022128157 | K20: =D27 -> 0.00015476754 | L20: =D28 -> 9.8042449e-05 | N20: 0.00089719644
B21: Column 3 | C21: 8.6396286e-05 | D21: 0.00013579362 | E21: =VARP('10Stocks_'!$C$1518:$C$3028) -> 0.00028082163 | F21: =E22 -> 0.00010160881 | G21: =E23 -> 8.6662554e-05 | H21: =E24 -> 9.5832082e-05 | I21: =E25 -> 0.00014026915 | J21: =E26 -> 0.0001565238 | K21: =E27 -> 0.00013173708 | L21: =E28 -> 0.00014321481 | N21: 0.00040281925 | P21: {=MMULT(_xlfn.ANCHORARRAY(P18),TRANSPOSE(B33:K33))} -> 0.00049566836
B22: Column 4 | C22: 7.9833364e-05 | D22: 0.00013076058 | E22: 0.00010160881 | F22: =VARP('10Stocks_'!$D$1518:$D$3028) -> 0.00018848503 | G22: =F23 -> 9.1763337e-05 | H22: =F24 -> 9.3516874e-05 | I22: =F25 -> 0.00013156761 | J22: =F26 -> 0.00013940383 | K22: =F27 -> 0.00013132847 | L22: =F28 -> 8.8054013e-05 | N22: 0.0008977099
B23: Column 5 | C23: 0.00010334608 | D23: 0.00017083205 | E23: 8.6662554e-05 | F23: 9.1763337e-05 | G23: =VARP('10Stocks_'!$E$1518:$E$3028) -> 0.00025577447 | H23: =G24 -> 0.00010777572 | I23: =G26 -> 0.00011886448 | J23: =G26 -> 0.00011886448 | K23: =G27 -> 0.00010798853 | L23: =G28 -> 7.4676417e-05 | N23: 0.00087825152
B24: Column 6 | C24: 9.1197689e-05 | D24: 0.0001261591 | E24: 9.5832082e-05 | F24: 9.3516874e-05 | G24: 0.00010777572 | H24: =VARP('10Stocks_'!$F$1518:$F$3028) -> 0.00021942533 | I24: =H25 -> 0.00011421713 | J24: =H26 -> 0.00013382218 | K24: =H27 -> 0.00011389576 | L24: =G28 -> 7.4676417e-05 | N24: 0.00074693549
B25: Column 7 | C25: 0.00012384515 | D25: 0.00021329347 | E25: 0.00014026915 | F25: 0.00013156761 | G25: 0.00013473204 | H25: 0.00011421713 | I25: =VARP('10Stocks_'!$G$1518:$G$3028) -> 0.0011700999 | J25: =I26 -> 0.00022268576 | K25: =I27 -> 0.0001369636 | L25: =H28 -> 8.1578374e-05 | N25: 0.0020281441
B26: Column 8 | C26: 0.00012624627 | D26: 0.00022128157 | E26: 0.0001565238 | F26: 0.00013940383 | G26: 0.00011886448 | H26: 0.00013382218 | I26: 0.00022268576 | J26: =VARP('10Stocks_'!$H$1518:$H$3028) -> 0.00061625395 | K26: =J27 -> 0.00017284956 | L26: =I28 -> 9.7438987e-05 | N26: 0.00081483095
B27: Column 9 | C27: 9.953054e-05 | D27: 0.00015476754 | E27: 0.00013173708 | F27: 0.00013132847 | G27: 0.00010798853 | H27: 0.00011389576 | I27: 0.0001369636 | J27: 0.00017284956 | K27: =VARP('10Stocks_'!$I$1518:$I$3028) -> 0.00024463544 | L27: =J28 -> 0.00011869148 | N27: 0.00062554756
B28: Column 10 | C28: 6.7677521e-05 | D28: 9.8042449e-05 | E28: 0.00014321481 | F28: 8.8054013e-05 | G28: 7.4676417e-05 | H28: 8.1578374e-05 | I28: 9.7438987e-05 | J28: 0.00011869148 | K28: 0.00011024513 | L28: =VARP('10Stocks_'!$J$1518:$J$3028) -> 0.00014332868 | N28: 0.00051131218
B32: appl | C32: bidu | D32: cop | E32: dis | F32: goog | G32: msft | H32: tesla | I32: ttm | J32: wfc | K32: xom
B33: 0 | C33: 0.00091083277 | D33: 0 | E33: 0.28745598 | F33: 0.1221091 | G33: 0 | H33: 0.58952409 | I33: 0 | J33: 0 | K33: 0
B37: =SUM(B33:K33) -> 1 | C37: `== | D37: 1
G39: var | H39: sd | I39: mean
B40: 0.0007 | D40: =AVERAGE(_xlfn.ANCHORARRAY('10Stocks_'!$K$1518)) -> 0.0015617516 | G40: 0.0001060443 | H40: =SQRT(G40) -> 0.010297781 | I40: 0.0007009991
B41: =B40+0.00003 -> 0.00073 | D41: =AVERAGE(_xlfn.ANCHORARRAY('10Stocks_'!$K$1518)) -> 0.0015617516 | G41: 0.0001064828 | H41: =SQRT(G41) -> 0.01031905 | I41: 0.00073
B42: =B41+0.00003 -> 0.00076 | D42: =AVERAGE(_xlfn.ANCHORARRAY('10Stocks_'!$K$1518)) -> 0.0015617516 | G42: 0.0001076324 | H42: =SQRT(G42) -> 0.010374604 | I42: 0.00076 | N42: =P21 -> 0.00049566836
B43: =B42+0.00003 -> 0.00079 | D43: =AVERAGE(_xlfn.ANCHORARRAY('10Stocks_'!$K$1518)) -> 0.0015617516 | G43: 0.00010948721 | H43: =SQRT(G43) -> 0.010463614 | I43: 0.00079
B44: =B43+0.00003 -> 0.00082 | D44: =AVERAGE(_xlfn.ANCHORARRAY('10Stocks_'!$K$1518)) -> 0.0015617516 | G44: 0.00011204722 | H44: =SQRT(G44) -> 0.010585236 | I44: 0.00082
B45: =B44+0.00003 -> 0.00085 | D45: =AVERAGE(_xlfn.ANCHORARRAY('10Stocks_'!$K$1518)) -> 0.0015617516 | G45: 0.00011531243 | H45: =SQRT(G45) -> 0.010738363 | I45: 0.00085
B46: =B45+0.00003 -> 0.00088 | D46: =AVERAGE(_xlfn.ANCHORARRAY('10Stocks_'!$K$1518)) -> 0.0015617516 | G46: 0.00011928285 | H46: =SQRT(G46) -> 0.010921669 | I46: 0.00088
B47: =B46+0.00003 -> 0.00091 | D47: =AVERAGE(_xlfn.ANCHORARRAY('10Stocks_'!$K$1518)) -> 0.0015617516 | G47: 0.00012395847 | H47: =SQRT(G47) -> 0.011133664 | I47: 0.00091
B48: =B47+0.00003 -> 0.00094 | D48: =AVERAGE(_xlfn.ANCHORARRAY('10Stocks_'!$K$1518)) -> 0.0015617516 | G48: 0.0001293393 | H48: =SQRT(G48) -> 0.011372744 | I48: 0.00094
B49: =B48+0.00003 -> 0.00097 | D49: =AVERAGE(_xlfn.ANCHORARRAY('10Stocks_'!$K$1518)) -> 0.0015617516 | G49: 0.00013542533 | H49: =SQRT(G49) -> 0.011637239 | I49: 0.00097
B50: =B49+0.00003 -> 0.001 | D50: =AVERAGE(_xlfn.ANCHORARRAY('10Stocks_'!$K$1518)) -> 0.0015617516 | G50: 0.00014221656 | H50: =SQRT(G50) -> 0.011925458 | I50: 0.001
B51: =B50+0.00003 -> 0.00103 | D51: =AVERAGE(_xlfn.ANCHORARRAY('10Stocks_'!$K$1518)) -> 0.0015617516 | G51: 0.000149713 | H51: =SQRT(G51) -> 0.012235726 | I51: 0.00103
...

Sheet 10Stocks
B1: Percent weights of 10 stocks. | I1: Percent weights of 10 stocks. | P1: Percent weights of 10 stocks.
C3: appl | D3: 0.17078954 | F3: Template | J3: appl | K3: 0.17078954 | M3: Constrained (No Shorting) | Q3: appl | R3: 0.20654926 | T3: Allows Shorting
C4: bidu | D4: 0 | J4: bidu | K4: 0 | Q4: bidu | R4: -0.015011141
C5: cop | D5: 0 | F5: Mean | G5: =AVERAGE('10Stocks_'!AE3:AE1513) -> 0.0010586116 | J5: cop | K5: 0 | M5: Mean | N5: 0.0010586116 | Q5: cop | R5: -0.24573753 | T5: Mean | U5: 0.001147494
C6: dis | D6: 0.387927 | F6: Median | G6: =MEDIAN('10Stocks_'!AE3:AE1513) -> 0.0011942636 | J6: dis | K6: 0.38792699 | M6: Median | N6: 0.0011942636 | Q6: dis | R6: 0.49699044 | T6: Median | U6: 0.0011485948
C7: goog | D7: 0.17471424 | F7: Standard Deviation | G7: =_xlfn.STDEV.S('10Stocks_'!AE3:AE1513) -> 0.012578596 | J7: goog | K7: 0.17471424 | M7: Standard Deviation | N7: 0.012578596 | Q7: goog | R7: 0.20095102 | T7: Standard Deviation | U7: 0.013045907
C8: msft | D8: 0.099172603 | F8: Sample Variance | G8: =_xlfn.VAR.S('10Stocks_'!AE3:AE1513) -> 0.00015822109 | J8: msft | K8: 0.099172599 | M8: Sample Variance | N8: 0.00015822109 | Q8: msft | R8: 0.15232145 | T8: Sample Variance | U8: 0.00017019568
C9: tesla | D9: 0.16739662 | F9: Kurtosis | G9: =KURT('10Stocks_'!AE3:AE1513) -> 1.5145689 | J9: tesla | K9: 0.16739662 | M9: Kurtosis | N9: 1.5145689 | Q9: tesla | R9: 0.17946369 | T9: Kurtosis | U9: 1.4061
C10: ttm | D10: 0 | F10: Minimum | G10: =MIN('10Stocks_'!AE3:AE1513) -> -0.061107346 | J10: ttm | K10: 0 | M10: Minimum | N10: -0.061107346 | Q10: ttm | R10: -0.021101522 | T10: Minimum | U10: -0.064869685
C11: wfc | D11: 0 | F11: Maximum | G11: =MAX('10Stocks_'!AE3:AE1513) -> 0.052946804 | J11: wfc | K11: 0 | M11: Maximum | N11: 0.052946804 | Q11: wfc | R11: -0.1742514 | T11: Maximum | U11: 0.053082419
C12: xom | D12: 0 | F12: Count | G12: =COUNT('10Stocks_'!AE3:AE1513) -> 1511 | J12: xom | K12: 0 | M12: Count | N12: 1511 | Q12: xom | R12: 0.21982573 | T12: Count | U12: 1511
F13: Confidence Level(95.0%) | G13: =_xlfn.CONFIDENCE.NORM(0.05,G7,G12) -> 0.00063423184 | M13: Confidence Level(95.0%) | N13: 0.00063423184 | T13: Confidence Level(95.0%) | U13: 0.00065779433
B14: Constraints | F14: Sharpe Ratio | G14: =G5/G7 -> 0.084159754 | I14: Constraints | M14: Sharpe Ratio | N14: 0.084159754 | P14: Constraints | T14: Sharpe Ratio | U14: 0.087958161
B15: 1 | C15: `== | D15: =SUM(D3:D12) -> 1 | I15: 1 | J15: `== | K15: 0.99999999 | P15: 1 | Q15: `== | R15: 0.99999999
L17: Monthly
L18: Mean | M18: =N5*21*100 -> 2.2230843
L19: SD | M19: =N7*N19*100 -> 5.764237 | N19: =SQRT(21) -> 4.5825757
L20: Sharpe | M20: =M18/M19 -> 0.38566844

Sheet ApplStock
B1: Apple Stock Analysis
C3: Apple Statistics
C5: Mean | D5: 0.00083929393
C6: Standard Error | D6: 0.0004248894
C7: Median | D7: 0.00063533441
C8: Mode | D8: #N/A
C9: Standard Deviation | D9: 0.016516124
C10: Sample Variance | D10: 0.00027278234
C11: Kurtosis | D11: 4.4418
C12: Skewness | D12: -0.1978243
C13: Range | D13: 0.21229933
C14: Minimum | D14: -0.12355796
C15: Maximum | D15: 0.088741367
C16: Sum | D16: 1.2681731
C17: Count | D17: 1511
C18: Confidence Level(95.0%) | D18: 0.00083343596
C19: Sharpe Ratio | D19: =D5/D9 -> 0.050816641
E21: Monthly | H21: 21
E22: Mean | F22: =D5*H21*100 -> 1.7625173 | H22: =SQRT(H21) -> 4.5825757
E23: SD | F23: =D9*H22*100 -> 7.5686387
E24: Sharpe | F24: =F22/F23 -> 0.2328711

Sheet VB+VF
C2: Percent weight of VBTLX and VFIAX
J3: 5000000
C4: VBTLX | D4: 0.67845909
C5: VFIAX | D5: 0.32154092 | G5: mean | H5: =AVERAGE('VB+VF_'!H2:H49) -> 0.005136616
B6: 1 | C6: `== | D6: =SUM(D4:D5) -> 1 | G6: var | H6: =_xlfn.VAR.S('VB+VF_'!H2:H49) -> 0.00011715492
G7: sd | H7: =_xlfn.STDEV.S('VB+VF_'!H2:H49) -> 0.010823813
G8: sharpe | H8: =H5/H7 -> 0.47456624
B11: VBTLX | C11: 0.67845909 | D11: =C11*J3 -> 3392295.4
B12: VFIAX | C12: 0.32154092 | D12: =C12*J3 -> 1607704.6
A14: monthly returns | C14: VBTLX | D14: VFIAX | E14: VBTLX | F14: VFIAX | G14: Total | H14: Return | K14: mean | L14: =AVERAGE(H15:H21) -> 0.0094518089
C15: =D11*'VB+VF_'!F50 -> 48849.054 | D15: =D12*'VB+VF_'!G50 -> -79902.918 | E15: =$D$11+C15 -> 3441144.5 | F15: =$D$12+D15 -> 1527801.7 | G15: =E15+F15 -> 4968946.2 | H15: =(G15-J3)/J3 -> -0.0062107685 | K15: var | L15: =_xlfn.VAR.S(H15:H21) -> 0.00012291776
C16: =(G15*$C$11)*'VB+VF_'!F51 -> 22587.219 | D16: =(G15*$C$12)*'VB+VF_'!G51 -> -2236.8073 | E16: =E15+C16 -> 3463731.7 | F16: =F15+D16 -> 1525564.9 | G16: =E16+F16 -> 4989296.6 | H16: =(G16-G15)/G15 -> 0.0040955186 | K16: sd | L16: =_xlfn.STDEV.S(H15:H21) -> 0.011086828
C17: =(G16*$C$11)*'VB+VF_'!F52 -> 32157.819 | D17: =(G16*$C$12)*'VB+VF_'!G52 -> 108769.03 | E17: =E16+C17 -> 3495889.5 | F17: =F16+D17 -> 1634333.9 | G17: =E17+F17 -> 5130223.4 | H17: =(G17-G16)/G16 -> 0.028245836 | K17: count | L17: =COUNT(H15:H21) -> 7
C18: =(G17*$C$11)*'VB+VF_'!F53 -> 13574.522 | D18: =(G17*$C$12)*'VB+VF_'!G53 -> 6433.3493 | E18: =E17+C18 -> 3509464 | F18: =F17+D18 -> 1640767.2 | G18: =E18+F18 -> 5150231.3 | H18: =(G18-G17)/G17 -> 0.0039 | K18: ci | L18: =_xlfn.CONFIDENCE.NORM(0.05,L16,L17) -> 0.0082130863
C19: =(G18*$C$11)*'VB+VF_'!F54 -> 698.84424 | D19: =(G18*$C$12)*'VB+VF_'!G54 -> 29642.581 | E19: =E18+C19 -> 3510162.9 | F19: =F18+D19 -> 1670409.8 | G19: =E19+F19 -> 5180572.7 | H19: =(G19-G18)/G18 -> 0.0058912742 | K19: sharpe | L19: =L14/L16 -> 0.85252597
C20: =(G19*$C$11)*'VB+VF_'!F55 -> 68187.249 | D20: =(G19*$C$12)*'VB+VF_'!G55 -> 4330.9919 | E20: =E19+C20 -> 3578350.1 | F20: =F19+D20 -> 1674740.8 | G20: =E20+F20 -> 5253091 | H20: =(G20-G19)/G19 -> 0.013998113
C21: =(G20*$C$11)*'VB+VF_'!F56 -> 23166.047 | D21: =(G20*$C$12)*'VB+VF_'!G56 -> 62158.28 | E21: =E20+C21 -> 3601516.2 | F21: =F20+D21 -> 1736899.1 | G21: =E21+F21 -> 5338415.3 | H21: =(G21-G20)/G20 -> 0.01624269
C22: =(G21*$C$11)*'VB+VF_'!F57 -> 0 | D22: =(G21*$C$12)*'VB+VF_'!G57 -> 0 | E22: =E21+C22 -> 3601516.2 | F22: =F21+D22 -> 1736899.1 | G22: =E22+F22 -> 5338415.3
C23: =(G22*$C$11)*'VB+VF_'!F58 -> 0 | D23: =(G22*$C$12)*'VB+VF_'!G58 -> 0 | E23: =E22+C23 -> 3601516.2 | F23: =F22+D23 -> 1736899.1 | G23: =E23+F23 -> 5338415.3
C24: =(G23*$C$11)*'VB+VF_'!F59 -> 0 | D24: =(G23*$C$12)*'VB+VF_'!G59 -> 0 | E24: =E23+C24 -> 3601516.2 | F24: =F23+D24 -> 1736899.1 | G24: =E24+F24 -> 5338415.3
C25: =(G24*$C$11)*'VB+VF_'!F60 -> 0 | D25: =(G24*$C$12)*'VB+VF_'!G60 -> 0 | E25: =E24+C25 -> 3601516.2 | F25: =F24+D25 -> 1736899.1 | G25: =E25+F25 -> 5338415.3
B29: VBTLX | C29: 0.67845909 | D29: =C29*J3 -> 3392295.4
B30: VFIAX | C30: 0.32154092 | D30: =C30*J3 -> 1607704.6
A32: monthly returns | C32: VBTLX | D32: VFIAX | E32: VBTLX | F32: VFIAX | G32: Total | H32: Return | K32: mean | L32: =AVERAGE(H33:H39) -> 0.0093116259
C33: =D29*'VB+VF_'!F50 -> 48849.054 | D33: =D30*'VB+VF_'!G50 -> -79902.918 | E33: =D29+C33 -> 3441144.5 | F33: =D30+D33 -> 1527801.7 | G33: =E33+F33 -> 4968946.2 | H33: =(G33-$J$3)/$J$3 -> -0.0062107685 | K33: var | L33: =_xlfn.VAR.S(H33:H39) -> 0.00011690475
C34: =E33*'VB+VF_'!F51 -> 23055.668 | D34: =F33*'VB+VF_'!G51 -> -2138.9223 | E34: =E33+C34 -> 3464200.2 | F34: =F33+D34 -> 1525662.7 | G34: =E34+F34 -> 4989862.9 | H34: =(G34-G33)/G33 -> 0.0042094933 | K34: sd | L34: =_xlfn.STDEV.S(H33:H39) -> 0.01081225
C35: =E34*'VB+VF_'!F52 -> 32909.901 | D35: =F34*'VB+VF_'!G52 -> 103439.93 | E35: =E34+C35 -> 3497110.1 | F35: =F34+D35 -> 1629102.7 | G35: =E35+F35 -> 5126212.7 | H35: =(G35-G34)/G34 -> 0.027325367 | K35: count | L35: =COUNT(H33:H39) -> 7
C36: =E35*'VB+VF_'!F53 -> 13638.729 | D36: =F35*'VB+VF_'!G53 -> 6353.5005 | E36: =E35+C36 -> 3510748.8 | F36: =F35+D36 -> 1635456.2 | G36: =E36+F36 -> 5146205 | H36: =(G36-G35)/G35 -> 0.0039 | K36: ci | L36: =_xlfn.CONFIDENCE.NORM(0.05,L34,L35) -> 0.0080096798
C37: =E36*'VB+VF_'!F54 -> 702.14976 | D37: =F36*'VB+VF_'!G54 -> 29274.666 | E37: =E36+C37 -> 3511450.9 | F37: =F36+D37 -> 1664730.8 | G37: =E37+F37 -> 5176181.8 | H37: =(G37-G36)/G36 -> 0.0058250333 | K37: sharpe | L37: =L32/L34 -> 0.86121074
C38: =E37*'VB+VF_'!F55 -> 68122.148 | D38: =F37*'VB+VF_'!G55 -> 4328.3002 | E38: =E37+C38 -> 3579573.1 | F38: =F37+D38 -> 1669059.1 | G38: =E38+F38 -> 5248632.2 | H38: =(G38-G37)/G37 -> 0.01399689
C39: =E38*'VB+VF_'!F56 -> 23267.225 | D39: =F38*'VB+VF_'!G56 -> 61421.377 | E39: =E38+C39 -> 3602840.3 | F39: =F38+D39 -> 1730480.5 | G39: =E39+F39 -> 5333320.8 | H39: =(G39-G38)/G38 -> 0.016135366
C40: =E39*'VB+VF_'!F57 -> 0 | D40: =F39*'VB+VF_'!G57 -> 0 | E40: =E39+C40 -> 3602840.3 | F40: =F39+D40 -> 1730480.5 | G40: =E40+F40 -> 5333320.8 | H40: =(G40-G39)/G39 -> 0
C41: =E40*'VB+VF_'!F58 -> 0 | D41: =F40*'VB+VF_'!G58 -> 0 | E41: =E40+C41 -> 3602840.3 | F41: =F40+D41 -> 1730480.5 | G41: =E41+F41 -> 5333320.8 | H41: =(G41-G40)/G40 -> 0
C42: =E41*'VB+VF_'!F59 -> 0 | D42: =F41*'VB+VF_'!G59 -> 0 | E42: =E41+C42 -> 3602840.3 | F42: =F41+D42 -> 1730480.5 | G42: =E42+F42 -> 5333320.8 | H42: =(G42-G41)/G41 -> 0
C43: =E42*'VB+VF_'!F60 -> 0 | D43: =F42*'VB+VF_'!G60 -> 0 | E43: =E42+C43 -> 3602840.3 | F43: =F42+D43 -> 1730480.5 | G43: =E43+F43 -> 5333320.8 | H43: =(G43-G42)/G42 -> 0

Sheet VB+VF_
A1: Date | B1: VBTLX | C1: VFIAX | E1: Date | F1: VBTLX | G1: VFIAX | I1: 100000
A2: 40909 | B2: 0.88 | C2: 4.47 | E2: 40909 | F2: =B2/100 -> 0.0088 | G2: =C2/100 -> 0.0447 | H2: =(F2*'VB+VF'!$D$4)+('VB+VF_'!G2*'VB+VF'!$D$5) -> 0.020343319 | I2: =I1+(I1*H2) -> 102034.33
A3: 40940 | B3: -0.04 | C3: 4.32 | E3: 40940 | F3: =B3/100 -> -0.0004 | G3: =C3/100 -> 0.0432 | H3: =(F3*'VB+VF'!$D$4)+('VB+VF_'!G3*'VB+VF'!$D$5) -> 0.013619184 | I3: =I2+(I2*H3) -> 103423.96
A4: 40969 | B4: -0.57 | C4: 3.29 | E4: 40969 | F4: =B4/100 -> -0.0057 | G4: =C4/100 -> 0.0329 | H4: =(F4*'VB+VF'!$D$4)+('VB+VF_'!G4*'VB+VF'!$D$5) -> 0.0067114794 | I4: =I3+(I3*H4) -> 104118.08
A5: 41000 | B5: 1.15 | C5: -0.63 | E5: 41000 | F5: =B5/100 -> 0.0115 | G5: =C5/100 -> -0.0063 | H5: =(F5*'VB+VF'!$D$4)+('VB+VF_'!G5*'VB+VF'!$D$5) -> 0.0057765717 | I5: =I4+(I4*H5) -> 104719.53 | L5: VBTLX & VFIAX Portfolio
A6: 41030 | B6: 0.96 | C6: -6.01 | E6: 41030 | F6: =B6/100 -> 0.0096 | G6: =C6/100 -> -0.0601 | H6: =(F6*'VB+VF'!$D$4)+('VB+VF_'!G6*'VB+VF'!$D$5) -> -0.012811402 | I6: =I5+(I5*H6) -> 103377.93
A7: 41061 | B7: 0.04 | C7: 4.12 | E7: 41061 | F7: =B7/100 -> 0.0004 | G7: =C7/100 -> 0.0412 | H7: =(F7*'VB+VF'!$D$4)+('VB+VF_'!G7*'VB+VF'!$D$5) -> 0.013518869 | I7: =I6+(I6*H7) -> 104775.48 | L7: Mean | M7: 0.0056858223
A8: 41091 | B8: 1.39 | C8: 1.38 | E8: 41091 | F8: =B8/100 -> 0.0139 | G8: =C8/100 -> 0.0138 | H8: =(F8*'VB+VF'!$D$4)+('VB+VF_'!G8*'VB+VF'!$D$5) -> 0.013867846 | I8: =I7+(I7*H8) -> 106228.49 | L8: Standard Error | M8: 0.0014630746
A9: 41122 | B9: 0.04 | C9: 2.25 | E9: 41122 | F9: =B9/100 -> 0.0004 | G9: =C9/100 -> 0.0225 | H9: =(F9*'VB+VF'!$D$4)+('VB+VF_'!G9*'VB+VF'!$D$5) -> 0.0075060543 | I9: =I8+(I8*H9) -> 107025.85 | L9: Median | M9: 0.0067114794
A10: 41153 | B10: 0.12 | C10: 2.58 | E10: 41153 | F10: =B10/100 -> 0.0012 | G10: =C10/100 -> 0.0258 | H10: =(F10*'VB+VF'!$D$4)+('VB+VF_'!G10*'VB+VF'!$D$5) -> 0.0091099066 | I10: =I9+(I9*H10) -> 108000.84 | L10: Mode | M10: #N/A
A11: 41183 | B11: 0.12 | C11: -1.85 | E11: 41183 | F11: =B11/100 -> 0.0012 | G11: =C11/100 -> -0.0185 | H11: =(F11*'VB+VF'!$D$4)+('VB+VF_'!G11*'VB+VF'!$D$5) -> -0.0051343561 | I11: =I10+(I10*H11) -> 107446.33 | L11: Standard Deviation | M11: 0.010850452
A12: 41214 | B12: 0.2 | C12: 0.58 | E12: 41214 | F12: =B12/100 -> 0.002 | G12: =C12/100 -> 0.0058 | H12: =(F12*'VB+VF'!$D$4)+('VB+VF_'!G12*'VB+VF'!$D$5) -> 0.0032218555 | I12: =I11+(I11*H12) -> 107792.5 | L12: Sample Variance | M12: 0.0001177323
A13: 41244 | B13: -0.19 | C13: 0.91 | E13: 41244 | F13: =B13/100 -> -0.0019 | G13: =C13/100 -> 0.0091 | H13: =(F13*'VB+VF'!$D$4)+('VB+VF_'!G13*'VB+VF'!$D$5) -> 0.0016369501 | I13: =I12+(I12*H13) -> 107968.95 | L13: Kurtosis | M13: -0.13992785
A14: 41275 | B14: -0.7 | C14: 5.18 | E14: 41275 | F14: =B14/100 -> -0.007 | G14: =C14/100 -> 0.0518 | H14: =(F14*'VB+VF'!$D$4)+('VB+VF_'!G14*'VB+VF'!$D$5) -> 0.011906606 | I14: =I13+(I13*H14) -> 109254.5 | L14: Skewness | M14: -0.32027855
A15: 41306 | B15: 0.55 | C15: 1.35 | E15: 41306 | F15: =B15/100 -> 0.0055 | G15: =C15/100 -> 0.0135 | H15: =(F15*'VB+VF'!$D$4)+('VB+VF_'!G15*'VB+VF'!$D$5) -> 0.0080723274 | I15: =I14+(I14*H15) -> 110136.44 | L15: Range | M15: 0.050041514
A16: 41334 | B16: 0.09 | C16: 3.75 | E16: 41334 | F16: =B16/100 -> 0.0009 | G16: =C16/100 -> 0.0375 | H16: =(F16*'VB+VF'!$D$4)+('VB+VF_'!G16*'VB+VF'!$D$5) -> 0.012668398 | I16: =I15+(I15*H16) -> 111531.69 | L16: Minimum | M16: -0.021795678
A17: 41365 | B17: 0.92 | C17: 1.92 | E17: 41365 | F17: =B17/100 -> 0.0092 | G17: =C17/100 -> 0.0192 | H17: =(F17*'VB+VF'!$D$4)+('VB+VF_'!G17*'VB+VF'!$D$5) -> 0.012415409 | I17: =I16+(I16*H17) -> 112916.4 | L17: Maximum | M17: 0.028245836
A18: 41395 | B18: -1.7 | C18: 2.33 | E18: 41395 | F18: =B18/100 -> -0.017 | G18: =C18/100 -> 0.0233 | H18: =(F18*'VB+VF'!$D$4)+('VB+VF_'!G18*'VB+VF'!$D$5) -> -0.0040419011 | I18: =I17+(I17*H18) -> 112460 | L18: Sum | M18: 0.31272022
A19: 41426 | B19: -1.64 | C19: -1.35 | E19: 41426 | F19: =B19/100 -> -0.0164 | G19: =C19/100 -> -0.0135 | H19: =(F19*'VB+VF'!$D$4)+('VB+VF_'!G19*'VB+VF'!$D$5) -> -0.015467531 | I19: =I18+(I18*H19) -> 110720.52 | L19: Count | M19: 55
A20: 41456 | B20: 0.21 | C20: 5.09 | E20: 41456 | F20: =B20/100 -> 0.0021 | G20: =C20/100 -> 0.0509 | H20: =(F20*'VB+VF'!$D$4)+('VB+VF_'!G20*'VB+VF'!$D$5) -> 0.017791197 | I20: =I19+(I19*H20) -> 112690.37 | L20: Confidence Level(95.0%) | M20: 0.002933288
A21: 41487 | B21: -0.63 | C21: -2.9 | E21: 41487 | F21: =B21/100 -> -0.0063 | G21: =C21/100 -> -0.029 | H21: =(F21*'VB+VF'!$D$4)+('VB+VF_'!G21*'VB+VF'!$D$5) -> -0.013598979 | I21: =I20+(I20*H21) -> 111157.9 | L21: Sharpe Ratio | M21: =M7/M11 -> 0.5240171
A22: 41518 | B22: 0.97 | C22: 3.13 | E22: 41518 | F22: =B22/100 -> 0.0097 | G22: =C22/100 -> 0.0313 | H22: =(F22*'VB+VF'!$D$4)+('VB+VF_'!G22*'VB+VF'!$D$5) -> 0.016645284 | I22: =I21+(I21*H22) -> 113008.15
A23: 41548 | B23: 0.79 | C23: 4.59 | E23: 41548 | F23: =B23/100 -> 0.0079 | G23: =C23/100 -> 0.0459 | H23: =(F23*'VB+VF'!$D$4)+('VB+VF_'!G23*'VB+VF'!$D$5) -> 0.020118555 | I23: =I22+(I22*H23) -> 115281.72
A24: 41579 | B24: -0.34 | C24: 3.04 | E24: 41579 | F24: =B24/100 -> -0.0034 | G24: =C24/100 -> 0.0304 | H24: =(F24*'VB+VF'!$D$4)+('VB+VF_'!G24*'VB+VF'!$D$5) -> 0.007468083 | I24: =I23+(I23*H24) -> 116142.65
A25: 41609 | B25: -0.64 | C25: 2.53 | E25: 41609 | F25: =B25/100 -> -0.0064 | G25: =C25/100 -> 0.0253 | H25: =(F25*'VB+VF'!$D$4)+('VB+VF_'!G25*'VB+VF'!$D$5) -> 0.0037928471 | I25: =I24+(I24*H25) -> 116583.16
A26: 41640 | B26: 1.55 | C26: -3.46 | E26: 41640 | F26: =B26/100 -> 0.0155 | G26: =C26/100 -> -0.0346 | H26: =(F26*'VB+VF'!$D$4)+('VB+VF_'!G26*'VB+VF'!$D$5) -> -0.00060919991 | I26: =I25+(I25*H26) -> 116512.14
A27: 41671 | B27: 0.49 | C27: 4.57 | E27: 41671 | F27: =B27/100 -> 0.0049 | G27: =C27/100 -> 0.0457 | H27: =(F27*'VB+VF'!$D$4)+('VB+VF_'!G27*'VB+VF'!$D$5) -> 0.018018869 | I27: =I26+(I26*H27) -> 118611.55
A28: 41699 | B28: -0.14 | C28: 0.84 | E28: 41699 | F28: =B28/100 -> -0.0014 | G28: =C28/100 -> 0.0084 | H28: =(F28*'VB+VF'!$D$4)+('VB+VF_'!G28*'VB+VF'!$D$5) -> 0.001751101 | I28: =I27+(I27*H28) -> 118819.26
A29: 41730 | B29: 0.78 | C29: 0.74 | E29: 41730 | F29: =B29/100 -> 0.0078 | G29: =C29/100 -> 0.0074 | H29: =(F29*'VB+VF'!$D$4)+('VB+VF_'!G29*'VB+VF'!$D$5) -> 0.0076713837 | I29: =I28+(I28*H29) -> 119730.76
A30: 41760 | B30: 1.06 | C30: 2.34 | E30: 41760 | F30: =B30/100 -> 0.0106 | G30: =C30/100 -> 0.0234 | H30: =(F30*'VB+VF'!$D$4)+('VB+VF_'!G30*'VB+VF'!$D$5) -> 0.014715724 | I30: =I29+(I29*H30) -> 121492.69
A31: 41791 | B31: 0.12 | C31: 2.06 | E31: 41791 | F31: =B31/100 -> 0.0012 | G31: =C31/100 -> 0.0206 | H31: =(F31*'VB+VF'!$D$4)+('VB+VF_'!G31*'VB+VF'!$D$5) -> 0.0074378938 | I31: =I30+(I30*H31) -> 122396.34
A32: 41821 | B32: -0.25 | C32: -1.38 | E32: 41821 | F32: =B32/100 -> -0.0025 | G32: =C32/100 -> -0.0138 | H32: =(F32*'VB+VF'!$D$4)+('VB+VF_'!G32*'VB+VF'!$D$5) -> -0.0061334124 | I32: =I31+(I31*H32) -> 121645.63
A33: 41852 | B33: 1.14 | C33: 4 | E33: 41852 | F33: =B33/100 -> 0.0114 | G33: =C33/100 -> 0.04 | H33: =(F33*'VB+VF'!$D$4)+('VB+VF_'!G33*'VB+VF'!$D$5) -> 0.02059607 | I33: =I32+(I32*H33) -> 124151.05
... A56: 42552 | B56: 0.65 | C56: 3.68 | E56: 42552 | F56: =B56/100 -> 0.0065 | G56: =C56/100 -> 0.0368 | H56: =(F56*'VB+VF'!$D$4)+('VB+VF_'!G56*'VB+VF'!$D$5) -> 0.01624269 | I56: =I55+(I55*H56) -> 136163.22

Sheet 10Stocks_
A1: Adj Close | B1: Close Return | C1: Adj Close Return | D1: Adj Close | E1: Close Return | F1: Adj Close Return | G1: Adj Close | H1: Close Return | I1: Adj Close Return | J1: Adj Close | K1: Close Return | L1: Adj Close Return | M1: Adj Close | N1: Close Return | O1: Adj Close Return | P1: Adj Close | Q1: Close Return | R1: Adj Close Return | S1: Adj Close | T1: Close Return | U1: Adj Close Return | V1: Adj Close | W1: Close Return | X1: Adj Close Return | Y1: Adj Close | Z1: Close Return | AA1: Adj Close Return | AB1: Adj Close | AC1: Close Return | AD1: Adj Close Return | AE1: Portfolio Return 10 stocks
A2: 33.075655 | D2: 68.080002 | G2: 29.174816 | J2: 28.872496 | M2: 222.25313 | P2: 19.541996 | S2: 23.83 | V2: 16.11441 | Y2: 22.132058 | AB2: 48.248732 | AF2: 100000
A3: 32.674586 | B3: =(#REF!-#REF!)/#REF! -> #REF! | C3: =(A3-A2)/A2 -> -0.012125807 | D3: 68.550003 | E3: =(B3-B2)/B2 -> #REF! | F3: =(D3-D2)/D2 -> 0.0069036573 | G3: 29.044067 | H3: =(E3-E2)/E2 -> #REF! | I3: =(G3-G2)/G2 -> -0.0044815707 | J3: 28.86333 | K3: =(H3-H2)/H2 -> #REF! | L3: =(J3-J2)/J2 -> -0.00031746476 | M3: 219.52586 | N3: =(K3-K2)/K2 -> #REF! | O3: =(M3-M2)/M2 -> -0.012271026 | P3: 19.669388 | Q3: =(N3-N2)/N2 -> #REF! | R3: =(P3-P2)/P2 -> 0.0065188837 | S3: 21.959999 | T3: =(Q3-Q2)/Q2 -> #REF! | U3: =(S3-S2)/S2 -> -0.078472556 | V3: 16.292521 | W3: =(T3-T2)/T2 -> #REF! | X3: =(V3-V2)/V2 -> 0.011052902 | Y3: 21.768953 | Z3: =(W3-W2)/W2 -> #REF! | AA3: =(Y3-Y2)/Y2 -> -0.016406292 | AB3: 47.859834 | AC3: =(Z3-Z2)/Z2 -> #REF! | AD3: =(AB3-AB2)/AB2 -> -0.008060274 | AE3: =(C3*'10Stocks'!$D$3)+(F3*'10Stocks'!$D$4)+('10Stocks_'!I3*'10Stocks'!$D$5)+('10Stocks_'!L3*'10Stocks'!$D$6)+('10Stocks_'!O3*'10Stocks'!$D$7)+('10Stocks_'!R3*'10Stocks'!$D$8)+('10Stocks_'!U3*'10Stocks'!$D$9)+('10Stocks_'!X3*'10Stocks'!$D$10)+('10Stocks_'!AA3*'10Stocks'!$D$11)+('10Stocks_'!AD3*'10Stocks'!$D$12) -> -0.016827583 | AF3: =AF2+(AF2*AE3) -> 98317.242
A4: 32.472078 | B4: =(#REF!-#REF!)/#REF! -> #REF! | C4: =(A4-A3)/A3 -> -0.006197722 | D4: 67.550003 | E4: =(B4-B3)/B3 -> #REF! | F4: =(D4-D3)/D3 -> -0.014587891 | G4: 29.014348 | H4: =(E4-E3)/E3 -> #REF! | I4: =(G4-G3)/G3 -> -0.0010232382 | J4: 28.762505 | K4: =(H4-H3)/H3 -> #REF! | L4: =(J4-J3)/J3 -> -0.0034931867 | M4: 218.05731 | N4: =(K4-K3)/K3 -> #REF! | O4: =(M4-M3)/M3 -> -0.0066896311 | P4: 19.76281 | Q4: =(N4-N3)/N3 -> #REF! | R4: =(P4-P3)/P3 -> 0.004749614 | S4: 19.200001 | T4: =(Q4-Q3)/Q3 -> #REF! | U4: =(S4-S3)/S3 -> -0.12568297 | V4: 16.086287 | W4: =(T4-T3)/T3 -> #REF! | X4: =(V4-V3)/V3 -> -0.012658201 | Y4: 21.509592 | Z4: =(W4-W3)/W3 -> #REF! | AA4: =(Y4-Y3)/Y3 -> -0.011914262 | AB4: 47.826016 | AC4: =(Z4-Z3)/Z3 -> #REF! | AD4: =(AB4-AB3)/AB3 -> -0.00070660504 | AE4: =(C4*'10Stocks'!$D$3)+(F4*'10Stocks'!$D$4)+('10Stocks_'!I4*'10Stocks'!$D$5)+('10Stocks_'!L4*'10Stocks'!$D$6)+('10Stocks_'!O4*'10Stocks'!$D$7)+('10Stocks_'!R4*'10Stocks'!$D$8)+('10Stocks_'!U4*'10Stocks'!$D$9)+('10Stocks_'!X4*'10Stocks'!$D$10)+('10Stocks_'!AA4*'10Stocks'!$D$11)+('10Stocks_'!AD4*'10Stocks'!$D$12) -> -0.024150255 | AF4: =AF3+(AF3*AE4) -> 95942.855
A5: 32.694309 | B5: =(#REF!-#REF!)/#REF! -> #REF! | C5: =(A5-A4)/A4 -> 0.0068437567 | D5: 67.449997 | E5: =(B5-B4)/B4 -> #REF! | F5: =(D5-D4)/D4 -> -0.0014804737 | G5: 29.240187 | H5: =(E5-E4)/E4 -> #REF! | I5: =(G5-G4)/G4 -> 0.0077837007 | J5: 29.074145 | K5: =(H5-H4)/H4 -> #REF! | L5: =(J5-J4)/J4 -> 0.010834939 | M5: 217.81756 | N5: =(K5-K4)/K4 -> #REF! | O5: =(M5-M4)/M4 -> -0.0010994678 | P5: 20.229915 | Q5: =(N5-N4)/N4 -> #REF! | R5: =(P5-P4)/P4 -> 0.023635556 | S5: 16.110001 | T5: =(Q5-Q4)/Q4 -> #REF! | U5: =(S5-S4)/S4 -> -0.16093749 | V5: 16.189405 | W5: =(T5-T4)/T4 -> #REF! | X5: =(V5-V4)/V4 -> 0.0064103046 | Y5: 21.743017 | Z5: =(W5-W4)/W4 -> #REF! | AA5: =(Y5-Y4)/Y4 -> 0.010852135 | AB5: 48.578449 | AC5: =(Z5-Z4)/Z4 -> #REF! | AD5: =(AB5-AB4)/AB4 -> 0.015732713 | AE5: =(C5*'10Stocks'!$D$3)+(F5*'10Stocks'!$D$4)+('10Stocks_'!I5*'10Stocks'!$D$5)+('10Stocks_'!L5*'10Stocks'!$D$6)+('10Stocks_'!O5*'10Stocks'!$D$7)+('10Stocks_'!R5*'10Stocks'!$D$8)+('10Stocks_'!U5*'10Stocks'!$D$9)+('10Stocks_'!X5*'10Stocks'!$D$10)+('10Stocks_'!AA5*'10Stocks'!$D$11)+('10Stocks_'!AD5*'10Stocks'!$D$12) -> -0.019416477 | AF5: =AF4+(AF4*AE5) -> 94079.983
A6: 34.01455 | B6: =(#REF!-#REF!)/#REF! -> #REF! | C6: =(A6-A5)/A5 -> 0.04038137 | D6: 72.370003 | E6: =(B6-B5)/B5 -> #REF! | F6: =(D6-D5)/D5 -> 0.072943013 | G6: 30.405046 | H6: =(E6-E5)/E5 -> #REF! | I6: =(G6-G5)/G5 -> 0.039837604 | J6: 30.375698 | K6: =(H6-H5)/H5 -> #REF! | L6: =(J6-J5)/J5 -> 0.044766682 | M6: 224.8755 | N6: =(K6-K5)/K5 -> #REF! | O6: =(M6-M5)/M5 -> 0.032402993 | P6: 20.63757 | Q6: =(N6-N5)/N5 -> #REF! | R6: =(P6-P5)/P5 -> 0.020151098 | S6: 15.8 | T6: =(Q6-Q5)/Q5 -> #REF! | U6: =(S6-S5)/S5 -> -0.019242767 | V6: 16.217526 | W6: =(T6-T5)/T5 -> #REF! | X6: =(V6-V5)/V5 -> 0.0017370002 | Y6: 23.048463 | Z6: =(W6-W5)/W5 -> #REF! | AA6: =(Y6-Y5)/Y5 -> 0.060039782 | AB6: 49.398518 | AC6: =(Z6-Z5)/Z5 -> #REF! | AD6: =(AB6-AB5)/AB5 -> 0.016881334 | AE6: =(C6*'10Stocks'!$D$3)+(F6*'10Stocks'!$D$4)+('10Stocks_'!I6*'10Stocks'!$D$5)+('10Stocks_'!L6*'10Stocks'!$D$6)+('10Stocks_'!O6*'10Stocks'!$D$7)+('10Stocks_'!R6*'10Stocks'!$D$8)+('10Stocks_'!U6*'10Stocks'!$D$9)+('10Stocks_'!X6*'10Stocks'!$D$10)+('10Stocks_'!AA6*'10Stocks'!$D$11)+('10Stocks_'!AD6*'10Stocks'!$D$12) -> 0.028701447 | AF6: =AF5+(AF5*AE6) -> 96780.215
A7: 33.938279 | B7: =(#REF!-#REF!)/#REF! -> #REF! | C7: =(A7-A6)/A6 -> -0.0022423051 | D7: 72.43 | E7: =(B7-B6)/B6 -> #REF! | F7: =(D7-D6)/D6 -> 0.00082903133 | G7: 30.636827 | H7: =(E7-E6)/E6 -> #REF! | I7: =(G7-G6)/G6 -> 0.0076231097 | J7: 30.559017 | K7: =(H7-H6)/H6 -> #REF! | L7: =(J7-J6)/J6 -> 0.0060350547 | M7: 228.05235 | N7: =(K7-K6)/K6 -> #REF! | O7: =(M7-M6)/M6 -> 0.01412711 | P7: 20.730992 | Q7: =(N7-N6)/N6 -> #REF! | R7: =(P7-P6)/P6 -> 0.0045267926 | S7: 17.459999 | T7: =(Q7-Q6)/Q6 -> #REF! | U7: =(S7-S6)/S6 -> 0.10506323 | V7: 16.461258 | W7: =(T7-T6)/T6 -> #REF! | X7: =(V7-V6)/V6 -> 0.015028926 | Y7: 23.031171 | Z7: =(W7-W6)/W6 -> #REF! | AA7: =(Y7-Y6)/Y6 -> -0.00075024525 | AB7: 49.719782 | AC7: =(Z7-Z6)/Z6 -> #REF! | AD7: =(AB7-AB6)/AB6 -> 0.0065035149 | AE7: =(C7*'10Stocks'!$D$3)+(F7*'10Stocks'!$D$4)+('10Stocks_'!I7*'10Stocks'!$D$5)+('10Stocks_'!L7*'10Stocks'!$D$6)+('10Stocks_'!O7*'10Stocks'!$D$7)+('10Stocks_'!R7*'10Stocks'!$D$8)+('10Stocks_'!U7*'10Stocks'!$D$9)+('10Stocks_'!X7*'10Stocks'!$D$10)+('10Stocks_'!AA7*'10Stocks'!$D$11)+('10Stocks_'!AD7*'10Stocks'!$D$12) -> 0.022462569 | AF7: =AF6+(AF6*AE7) -> 98954.147
A8: 34.139471 | B8: =(#REF!-#REF!)/#REF! -> #REF! | C8: =(A8-A7)/A7 -> 0.0059281733 | D8: 71.199997 | E8: =(B8-B7)/B7 -> #REF! | F8: =(D8-D7)/D7 -> -0.016981955 | G8: 31.082563 | H8: =(E8-E7)/E7 -> #REF! | I8: =(G8-G7)/G7 -> 0.014549026 | J8: 30.934817 | K8: =(H8-H7)/H7 -> #REF! | L8: =(J8-J7)/J7 -> 0.012297516 | M8: 233.51188 | N8: =(K8-K7)/K7 -> #REF! | O8: =(M8-M7)/M7 -> 0.023939842 | P8: 20.612093 | Q8: =(N8-N7)/N7 -> #REF! | R8: =(P8-P7)/P7 -> -0.0057353261 | S8: 17.4 | T8: =(Q8-Q7)/Q7 -> #REF! | U8: =(S8-S7)/S7 -> -0.003436369 | V8: 16.545627 | W8: =(T8-T7)/T7 -> #REF! | X8: =(V8-V7)/V7 -> 0.0051253069 | Y8: 23.342404 | Z8: =(W8-W7)/W7 -> #REF! | AA8: =(Y8-Y7)/Y7 -> 0.013513555 | AB8: 49.694417 | AC8: =(Z8-Z7)/Z7 -> #REF! | AD8: =(AB8-AB7)/AB7 -> -0.00051015912 | AE8: =(C8*'10Stocks'!$D$3)+(F8*'10Stocks'!$D$4)+('10Stocks_'!I8*'10Stocks'!$D$5)+('10Stocks_'!L8*'10Stocks'!$D$6)+('10Stocks_'!O8*'10Stocks'!$D$7)+('10Stocks_'!R8*'10Stocks'!$D$8)+('10Stocks_'!U8*'10Stocks'!$D$9)+('10Stocks_'!X8*'10Stocks'!$D$10)+('10Stocks_'!AA8*'10Stocks'!$D$11)+('10Stocks_'!AD8*'10Stocks'!$D$12) -> 0.0088216158 | AF8: =AF7+(AF7*AE8) -> 99827.082
A9: 33.833082 | B9: =(#REF!-#REF!)/#REF! -> #REF! | C9: =(A9-A8)/A8 -> -0.0089746265 | D9: 70.730003 | E9: =(B9-B8)/B8 -> #REF! | F9: =(D9-D8)/D8 -> -0.0066010396 | G9: 30.963696 | H9: =(E9-E8)/E8 -> #REF! | I9: =(G9-G8)/G8 -> -0.0038242342 | J9: 30.953149 | K9: =(H9-H8)/H8 -> #REF! | L9: =(J9-J8)/J8 -> 0.00059260089 | M9: 237.67773 | N9: =(K9-K8)/K8 -> #REF! | O9: =(M9-M8)/M8 -> 0.017839983 | P9: 21.08769 | Q9: =(N9-N8)/N8 -> #REF! | R9: =(P9-P8)/P8 -> 0.023073688 | S9: 17.049999 | T9: =(Q9-Q8)/Q8 -> #REF! | U9: =(S9-S8)/S8 -> -0.020115 | V9: 16.695615 | W9: =(T9-T8)/T8 -> #REF! | X9: =(V9-V8)/V8 -> 0.0090651143 | Y9: 23.394276 | Z9: =(W9-W8)/W8 -> #REF! | AA9: =(Y9-Y8)/Y8 -> 0.0022222218 | AB9: 49.829686 | AC9: =(Z9-Z8)/Z8 -> #REF! | AD9: =(AB9-AB8)/AB8 -> 0.002722016 | AE9: =(C9*'10Stocks'!$D$3)+(F9*'10Stocks'!$D$4)+('10Stocks_'!I9*'10Stocks'!$D$5)+('10Stocks_'!L9*'10Stocks'!$D$6)+('10Stocks_'!O9*'10Stocks'!$D$7)+('10Stocks_'!R9*'10Stocks'!$D$8)+('10Stocks_'!U9*'10Stocks'!$D$9)+('10Stocks_'!X9*'10Stocks'!$D$10)+('10Stocks_'!AA9*'10Stocks'!$D$11)+('10Stocks_'!AD9*'10Stocks'!$D$12) -> 0.00073510727 | AF9: =AF8+(AF8*AE9) -> 99900.466
A10: 33.111158 | B10: =(#REF!-#REF!)/#REF! -> #REF! | C10: =(A10-A9)/A9 -> -0.021337814 | D10: 74.379997 | E10: =(B10-B9)/B9 -> #REF! | F10: =(D10-D9)/D9 -> 0.051604607 | G10: 31.629332 | H10: =(E10-E9)/E9 -> #REF! | I10: =(G10-G9)/G9 -> 0.021497304 | J10: 31.576429 | K10: =(H10-H9)/H9 -> #REF! | L10: =(J10-J9)/J9 -> 0.020136239 | M10: 244.35606 | N10: =(K10-K9)/K9 -> #REF! | O10: =(M10-M9)/M9 -> 0.028098257 | P10: 21.342475 | Q10: =(N10-N9)/N9 -> #REF! | R10: =(P10-P9)/P9 -> 0.012082167 | S10: 18.139999 | T10: =(Q10-Q9)/Q9 -> #REF! | U10: =(S10-S9)/S9 -> 0.063929623 | V10: 17.361191 | W10: =(T10-T9)/T9 -> #REF! | X10: =(V10-V9)/V9 -> 0.039865318 | Y10: 24.155066 | Z10: =(W10-W9)/W9 -> #REF! | AA10: =(Y10-Y9)/Y9 -> 0.032520348 | AB10: 50.235493 | AC10: =(Z10-Z9)/Z9 -> #REF! | AD10: =(AB10-AB9)/AB9 -> 0.0081438803 | AE10: =(C10*'10Stocks'!$D$3)+(F10*'10Stocks'!$D$4)+('10Stocks_'!I10*'10Stocks'!$D$5)+('10Stocks_'!L10*'10Stocks'!$D$6)+('10Stocks_'!O10*'10Stocks'!$D$7)+('10Stocks_'!R10*'10Stocks'!$D$8)+('10Stocks_'!U10*'10Stocks'!$D$9)+('10Stocks_'!X10*'10Stocks'!$D$10)+('10Stocks_'!AA10*'10Stocks'!$D$11)+('10Stocks_'!AD10*'10Stocks'!$D$12) -> 0.020976103 | AF10: =AF9+(AF9*AE10) -> 101995.99
A11: 33.233452 | B11: =(#REF!-#REF!)/#REF! -> #REF! | C11: =(A11-A10)/A10 -> 0.0036934377 | D11: 75.029999 | E11: =(B11-B10)/B10 -> #REF! | F11: =(D11-D10)/D10 -> 0.0087389356 | G11: 31.379713 | H11: =(E11-E10)/E10 -> #REF! | I11: =(G11-G10)/G10 -> -0.0078920099 | J11: 31.383946 | K11: =(H11-H10)/H10 -> #REF! | L11: =(J11-J10)/J10 -> -0.0060957811 | M11: 245.425 | N11: =(K11-K10)/K10 -> #REF! | O11: =(M11-M10)/M10 -> 0.0043745099 | P11: 21.605753 | Q11: =(N11-N10)/N10 -> #REF! | R11: =(P11-P10)/P10 -> 0.01233587 | S11: 19.84 | T11: =(Q11-Q10)/Q10 -> #REF! | U11: =(S11-S10)/S10 -> 0.093715606 | V11: 16.873728 | W11: =(T11-T10)/T10 -> #REF! | X11: =(V11-V10)/V10 -> -0.02807774 | Y11: 23.912996 | Z11: =(W11-W10)/W10 -> #REF! | AA11: =(Y11-Y10)/Y10 -> -0.0100215 | AB11: 50.100224 | AC11: =(Z11-Z10)/Z10 -> #REF! | AD11: =(AB11-AB10)/AB10 -> -0.0026926978 | AE11: =(C11*'10Stocks'!$D$3)+(F11*'10Stocks'!$D$4)+('10Stocks_'!I11*'10Stocks'!$D$5)+('10Stocks_'!L11*'10Stocks'!$D$6)+('10Stocks_'!O11*'10Stocks'!$D$7)+('10Stocks_'!R11*'10Stocks'!$D$8)+('10Stocks_'!U11*'10Stocks'!$D$9)+('10Stocks_'!X11*'10Stocks'!$D$10)+('10Stocks_'!AA11*'10Stocks'!$D$11)+('10Stocks_'!AD11*'10Stocks'!$D$12) -> 0.015941428 | AF11: =AF10+(AF10*AE11) -> 103621.95
A12: 33.065135 | B12: =(#REF!-#REF!)/#REF! -> #REF! | C12: =(A12-A11)/A11 -> -0.005064686 | D12: 75.639999 | E12: =(B12-B11)/B11 -> #REF! | F12: =(D12-D11)/D11 -> 0.0081300814 | G12: 31.415374 | H12: =(E12-E11)/E11 -> #REF! | I12: =(G12-G11)/G11 -> 0.0011364349 | J12: 31.209793 | K12: =(H12-H11)/H11 -> #REF! | L12: =(J12-J11)/J11 -> -0.005549111 | M12: 246.76366 | N12: =(K12-K11)/K11 -> #REF! | O12: =(M12-M11)/M11 -> 0.0054544525 | P12: 21.665203 | Q12: =(N12-N11)/N11 -> #REF! | R12: =(P12-P11)/P11 -> 0.002751582 | S12: 19.889999 | T12: =(Q12-Q11)/Q11 -> #REF! | U12: =(S12-S11)/S11 -> 0.0025201109 | V12: 17.014342 | W12: =(T12-T11)/T11 -> #REF! | X12: =(V12-V11)/V11 -> 0.0083333096 | Y12: 24.042676 | Z12: =(W12-W11)/W11 -> #REF! | AA12: =(Y12-Y11)/Y11 -> 0.0054229926 | AB12: 50.10868 | AC12: =(Z12-Z11)/Z11 -> #REF! | AD12: =(AB12-AB11)/AB11 -> 0.00016878168 | AE12: =(C12*'10Stocks'!$D$3)+(F12*'10Stocks'!$D$4)+('10Stocks_'!I12*'10Stocks'!$D$5)+('10Stocks_'!L12*'10Stocks'!$D$6)+('10Stocks_'!O12*'10Stocks'!$D$7)+('10Stocks_'!R12*'10Stocks'!$D$8)+('10Stocks_'!U12*'10Stocks'!$D$9)+('10Stocks_'!X12*'10Stocks'!$D$10)+('10Stocks_'!AA12*'10Stocks'!$D$11)+('10Stocks_'!AD12*'10Stocks'!$D$12) -> -0.0013699353 | AF12: =AF11+(AF11*AE12) -> 103479.99
A13: 32.861314 | B13: =(#REF!-#REF!)/#REF! -> #REF! | C13: =(A13-A12)/A12 -> -0.0061642271 | D13: 73.529999 | E13: =(B13-B12)/B12 -> #REF! | F13: =(D13-D12)/D12 -> -0.027895294 | G13: 30.815118 | H13: =(E13-E12)/E12 -> #REF! | I13: =(G13-G12)/G12 -> -0.019107078 | J13: 30.274873 | K13: =(H13-H12)/H12 -> #REF! | L13: =(J13-J12)/J12 -> -0.029955982 | M13: 229.57582 | N13: =(K13-K12)/K12 -> #REF! | O13: =(M13-M12)/M12 -> -0.069653028 | P13: 21.138647 | Q13: =(N13-N12)/N12 -> #REF! | R13: =(P13-P12)/P12 -> -0.024304226 | S13: 20.639999 | T13: =(Q13-Q12)/Q12 -> #REF! | U13: =(S13-S12)/S12 -> 0.037707393 | V13: 16.939347 | W13: =(T13-T12)/T12 -> #REF! | X13: =(V13-V12)/V12 -> -0.004407752 | Y13: 22.685358 | Z13: =(W13-W12)/W12 -> #REF! | AA13: =(Y13-Y12)/Y12 -> -0.056454531 | AB13: 49.001164 | AC13: =(Z13-Z12)/Z12 -> #REF! | AD13: =(AB13-AB12)/AB12 -> -0.022102278 | AE13: =(C13*'10Stocks'!$D$3)+(F13*'10Stocks'!$D$4)+('10Stocks_'!I13*'10Stocks'!$D$5)+('10Stocks_'!L13*'10Stocks'!$D$6)+('10Stocks_'!O13*'10Stocks'!$D$7)+('10Stocks_'!R13*'10Stocks'!$D$8)+('10Stocks_'!U13*'10Stocks'!$D$9)+('10Stocks_'!X13*'10Stocks'!$D$10)+('10Stocks_'!AA13*'10Stocks'!$D$11)+('10Stocks_'!AD13*'10Stocks'!$D$12) -> -0.020941119 | AF13: =AF12+(AF12*AE13) -> 101313.01
A14: 32.293244 | B14: =(#REF!-#REF!)/#REF! -> #REF! | C14: =(A14-A13)/A13 -> -0.017286892 | D14: 72.900002 | E14: =(B14-B13)/B13 -> #REF! | F14: =(D14-D13)/D13 -> -0.0085678908 | G14: 30.809176 | H14: =(E14-E13)/E13 -> #REF! | I14: =(G14-G13)/G13 -> -0.00019282743 | J14: 30.53152 | K14: =(H14-H13)/H13 -> #REF! | L14: =(J14-J13)/J13 -> 0.008477228 | M14: 232.85755 | N14: =(K14-K13)/K13 -> #REF! | O14: =(M14-M13)/M13 -> 0.014294737 | P14: 21.427403 | Q14: =(N14-N13)/N13 -> #REF! | R14: =(P14-P13)/P13 -> 0.013660098 | S14: 21.91 | T14: =(Q14-Q13)/Q13 -> #REF! | U14: =(S14-S13)/S13 -> 0.061531059 | V14: 17.126834 | W14: =(T14-T13)/T13 -> #REF! | X14: =(V14-V13)/V13 -> 0.011068136 | Y14: 22.495162 | Z14: =(W14-W13)/W13 -> #REF! | AA14: =(Y14-Y13)/Y13 -> -0.0083840863 | AB14: 49.398518 | AC14: =(Z14-Z13)/Z13 -> #REF! | AD14: =(AB14-AB13)/AB13 -> 0.0081090727 | AE14: =(C14*'10Stocks'!$D$3)+(F14*'10Stocks'!$D$4)+('10Stocks_'!I14*'10Stocks'!$D$5)+('10Stocks_'!L14*'10Stocks'!$D$6)+('10Stocks_'!O14*'10Stocks'!$D$7)+('10Stocks_'!R14*'10Stocks'!$D$8)+('10Stocks_'!U14*'10Stocks'!$D$9)+('10Stocks_'!X14*'10Stocks'!$D$10)+('10Stocks_'!AA14*'10Stocks'!$D$11)+('10Stocks_'!AD14*'10Stocks'!$D$12) -> 0.014488418 | AF14: =AF13+(AF13*AE14) -> 102780.87
... A381: 53.27241 | B381: =(#REF!-#REF!)/#REF! -> #REF! | C381: =(A381-A380)/A380 -> 0.0061593545 | D381: 114.72 | E381: =(B381-B380)/B380 -> #REF! | F381: =(D381-D380)/D380 -> -0.015278961 | G381: 45.788639 | H381: =(E381-E380)/E380 -> #REF! | I381: =(G381-G380)/G380 -> 0.014619823 | J381: 35.529341 | K381: =(H381-H380)/H380 -> #REF! | L381: =(J381-J380)/J380 -> 0.012620772 | M381: 320.87966 | N381: =(K381-K380)/K380 -> #REF! | O381: =(M381-M380)/M380 -> 0.00422067 | P381: 22.94657 | Q381: =(N381-N380)/N380 -> #REF! | R381: =(P381-P380)/P380 -> 0.0077459598 | S381: 28.73 | T381: =(Q381-Q380)/Q380 -> #REF! | U381: =(S381-S380)/S380 -> 0.0077165907 | V381: 16.412553 | W381: =(T381-T380)/T380 -> #REF! | X381: =(V381-V380)/V380 -> 0.021160683 | Y381: 24.503553 | Z381: =(W381-W380)/W380 -> #REF! | AA381: =(Y381-Y380)/Y380 -> 0.023976378 | AB381: 74.795314 | AC381: =(Z381-Z380)/Z380 -> #REF! | AD381: =(AB381-AB380)/AB380 -> 0.012948391 | AE381: =(C381*'10Stocks'!$D$3)+(F381*'10Stocks'!$D$4)+('10Stocks_'!I381*'10Stocks'!$D$5)+('10Stocks_'!L381*'10Stocks'!$D$6)+('10Stocks_'!O381*'10Stocks'!$D$7)+('10Stocks_'!R381*'10Stocks'!$D$8)+('10Stocks_'!U381*'10Stocks'!$D$9)+('10Stocks_'!X381*'10Stocks'!$D$10)+('10Stocks_'!AA381*'10Stocks'!$D$11)+('10Stocks_'!AD381*'10Stocks'!$D$12) -> 0.0087452209 | AF381: =AF380+(AF380*AE381) -> 137531.13
A382: 53.25663 | B382: =(#REF!-#REF!)/#REF! -> #REF! | C382: =(A382-A381)/A381 -> -0.00029621337 | D382: 116.47 | E382: =(B382-B381)/B381 -> #REF! | F382: =(D382-D381)/D381 -> 0.015254533 | G382: 45.788639 | H382: =(E382-E381)/E381 -> #REF! | I382: =(G382-G381)/G381 -> 0 | J382: 35.331485 | K382: =(H382-H381)/H381 -> #REF! | L382: =(J382-J381)/J381 -> -0.0055688058 | M382: 322.62792 | N382: =(K382-K381)/K381 -> #REF! | O382: =(M382-M381)/M381 -> 0.0054483322 | P382: 22.893656 | Q382: =(N382-N381)/N381 -> #REF! | R382: =(P382-P381)/P381 -> -0.0023059656 | S382: 28.559999 | T382: =(Q382-Q381)/Q381 -> #REF! | U382: =(S382-S381)/S381 -> -0.0059171946 | V382: 16.422271 | W382: =(T382-T381)/T381 -> #REF! | X382: =(V382-V381)/V381 -> 0.00059210776 | Y382: 24.327013 | Z382: =(W382-W381)/W381 -> #REF! | AA382: =(Y382-Y381)/Y381 -> -0.0072046695 | AB382: 74.347968 | AC382: =(Z382-Z381)/Z381 -> #REF! | AD382: =(AB382-AB381)/AB381 -> -0.0059809362 | AE382: =(C382*'10Stocks'!$D$3)+(F382*'10Stocks'!$D$4)+('10Stocks_'!I382*'10Stocks'!$D$5)+('10Stocks_'!L382*'10Stocks'!$D$6)+('10Stocks_'!O382*'10Stocks'!$D$7)+('10Stocks_'!R382*'10Stocks'!$D$8)+('10Stocks_'!U382*'10Stocks'!$D$9)+('10Stocks_'!X382*'10Stocks'!$D$10)+('10Stocks_'!AA382*'10Stocks'!$D$11)+('10Stocks_'!AD382*'10Stocks'!$D$12) -> -0.002478186 | AF382: =AF381+(AF381*AE382) -> 137190.31 | AG382: 100000
A383: 54.075861 | B383: =(#REF!-#REF!)/#REF! -> #REF! | C383: =(A383-A382)/A382 -> 0.015382704 | D383: 124.29 | E383: =(B383-B382)/B382 -> #REF! | F383: =(D383-D382)/D382 -> 0.067141753 | G383: 46.605506 | H383: =(E383-E382)/E382 -> #REF! | I383: =(G383-G382)/G382 -> 0.017839949 | J383: 36.094647 | K383: =(H383-H382)/H382 -> #REF! | L383: =(J383-J382)/J382 -> 0.021600054 | M383: 332.37319 | N383: =(K383-K382)/K382 -> #REF! | O383: =(M383-M382)/M382 -> 0.030205898 | P383: 23.607982 | Q383: =(N383-N382)/N382 -> #REF! | R383: =(P383-P382)/P382 -> 0.031201919 | S383: 28.08 | T383: =(Q383-Q382)/Q382 -> #REF! | U383: =(S383-S382)/S382 -> -0.016806688 | V383: 17.598067 | W383: =(T383-T382)/T382 -> #REF! | X383: =(V383-V382)/V382 -> 0.071597649 | Y383: 25.094957 | Z383: =(W383-W382)/W382 -> #REF! | AA383: =(Y383-Y382)/Y382 -> 0.031567542 | AB383: 75.435643 | AC383: =(Z383-Z382)/Z382 -> #REF! | AD383: =(AB383-AB382)/AB382 -> 0.014629519 | AE383: =(C383*'10Stocks'!$D$3)+(F383*'10Stocks'!$D$4)+('10Stocks_'!I383*'10Stocks'!$D$5)+('10Stocks_'!L383*'10Stocks'!$D$6)+('10Stocks_'!O383*'10Stocks'!$D$7)+('10Stocks_'!R383*'10Stocks'!$D$8)+('10Stocks_'!U383*'10Stocks'!$D$9)+('10Stocks_'!X383*'10Stocks'!$D$10)+('10Stocks_'!AA383*'10Stocks'!$D$11)+('10Stocks_'!AD383*'10Stocks'!$D$12) -> 0.016564842 | AF383: =AF382+(AF382*AE383) -> 139462.84 | AG383: =AG382+(AG382*AE383) -> 101656.48
A384: 54.366473 | B384: =(#REF!-#REF!)/#REF! -> #REF! | C384: =(A384-A383)/A383 -> 0.0053741539 | D384: 121.99 | E384: =(B384-B383)/B383 -> #REF! | F384: =(D384-D383)/D383 -> -0.018505133 | G384: 46.385582 | H384: =(E384-E383)/E383 -> #REF! | I384: =(G384-G383)/G383 -> -0.0047188416 | J384: 36.603417 | K384: =(H384-H383)/H383 -> #REF! | L384: =(J384-J383)/J383 -> 0.014095442 | M384: 333.80677 | N384: =(K384-K383)/K383 -> #REF! | O384: =(M384-M383)/M383 -> 0.0043131759 | P384: 24.163567 | Q384: =(N384-N383)/N383 -> #REF! | R384: =(P384-P383)/P383 -> 0.023533778 | S384: 27.709999 | T384: =(Q384-Q383)/Q383 -> #REF! | U384: =(S384-S383)/S383 -> -0.013176674 | V384: 18.258846 | W384: =(T384-T383)/T383 -> #REF! | X384: =(V384-V383)/V383 -> 0.037548385 | Y384: 25.209706 | Z384: =(W384-W383)/W383 -> #REF! | AA384: =(Y384-Y383)/Y383 -> 0.004572592 | AB384: 75.453183 | AC384: =(Z384-Z383)/Z383 -> #REF! | AD384: =(AB384-AB383)/AB383 -> 0.00023251608 | AE384: =(C384*'10Stocks'!$D$3)+(F384*'10Stocks'!$D$4)+('10Stocks_'!I384*'10Stocks'!$D$5)+('10Stocks_'!L384*'10Stocks'!$D$6)+('10Stocks_'!O384*'10Stocks'!$D$7)+('10Stocks_'!R384*'10Stocks'!$D$8)+('10Stocks_'!U384*'10Stocks'!$D$9)+('10Stocks_'!X384*'10Stocks'!$D$10)+('10Stocks_'!AA384*'10Stocks'!$D$11)+('10Stocks_'!AD384*'10Stocks'!$D$12) -> 0.0072676003 | AF384: =AF383+(AF383*AE384) -> 140476.4 | AG384: =AG383+(AG383*AE384) -> 102395.28
A385: 54.970046 | B385: =(#REF!-#REF!)/#REF! -> #REF! | C385: =(A385-A384)/A384 -> 0.011101934 | D385: 123.27 | E385: =(B385-B384)/B384 -> #REF! | F385: =(D385-D384)/D384 -> 0.010492655 | G385: 46.014845 | H385: =(E385-E384)/E384 -> #REF! | I385: =(G385-G384)/G384 -> -0.0079925051 | J385: 37.215831 | K385: =(H385-H384)/H384 -> #REF! | L385: =(J385-J384)/J384 -> 0.016731061 | M385: 329.17638 | N385: =(K385-K384)/K384 -> #REF! | O385: =(M385-M384)/M384 -> -0.013871474 | P385: 24.410494 | Q385: =(N385-N384)/N384 -> #REF! | R385: =(P385-P384)/P384 -> 0.01021898 | S385: 27.120001 | T385: =(Q385-Q384)/Q384 -> #REF! | U385: =(S385-S384)/S384 -> -0.021291881 | V385: 18.560082 | W385: =(T385-T384)/T384 -> #REF! | X385: =(V385-V384)/V384 -> 0.016498085 | Y385: 25.615746 | Z385: =(W385-W384)/W384 -> #REF! | AA385: =(Y385-Y384)/Y384 -> 0.016106495 | AB385: 75.225127 | AC385: =(Z385-Z384)/Z384 -> #REF! | AD385: =(AB385-AB384)/AB384 -> -0.0030224835 | AE385: =(C385*'10Stocks'!$D$3)+(F385*'10Stocks'!$D$4)+('10Stocks_'!I385*'10Stocks'!$D$5)+('10Stocks_'!L385*'10Stocks'!$D$6)+('10Stocks_'!O385*'10Stocks'!$D$7)+('10Stocks_'!R385*'10Stocks'!$D$8)+('10Stocks_'!U385*'10Stocks'!$D$9)+('10Stocks_'!X385*'10Stocks'!$D$10)+('10Stocks_'!AA385*'10Stocks'!$D$11)+('10Stocks_'!AD385*'10Stocks'!$D$12) -> 0.0034122344 | AF385: =AF384+(AF384*AE385) -> 140955.74 | AG385: =AG384+(AG384*AE385) -> 102744.68
A386: 55.544693 | B386: =(#REF!-#REF!)/#REF! -> #REF! | C386: =(A386-A385)/A385 -> 0.010453821 | D386: 121.09 | E386: =(B386-B385)/B385 -> #REF! | F386: =(D386-D385)/D385 -> -0.017684766 | G386: 45.65668 | H386: =(E386-E385)/E385 -> #REF! | I386: =(G386-G385)/G385 -> -0.0077836837 | J386: 37.602122 | K386: =(H386-H385)/H385 -> #REF! | L386: =(J386-J385)/J385 -> 0.010379749 | M386: 324.68586 | N386: =(K386-K385)/K385 -> #REF! | O386: =(M386-M385)/M385 -> -0.013641662 | P386: 24.789704 | Q386: =(N386-N385)/N385 -> #REF! | R386: =(P386-P385)/P385 -> 0.015534712 | S386: 26.91 | T386: =(Q386-Q385)/Q385 -> #REF! | U386: =(S386-S385)/S385 -> -0.0077433994 | V386: 18.511494 | W386: =(T386-T385)/T385 -> #REF! | X386: =(V386-V385)/V385 -> -0.0026178764 | Y386: 25.545131 | Z386: =(W386-W385)/W385 -> #REF! | AA386: =(Y386-Y385)/Y385 -> -0.0027567028 | AB386: 74.663746 | AC386: =(Z386-Z385)/Z385 -> #REF! | AD386: =(AB386-AB385)/AB385 -> -0.0074626793 | AE386: =(C386*'10Stocks'!$D$3)+(F386*'10Stocks'!$D$4)+('10Stocks_'!I386*'10Stocks'!$D$5)+('10Stocks_'!L386*'10Stocks'!$D$6)+('10Stocks_'!O386*'10Stocks'!$D$7)+('10Stocks_'!R386*'10Stocks'!$D$8)+('10Stocks_'!U386*'10Stocks'!$D$9)+('10Stocks_'!X386*'10Stocks'!$D$10)+('10Stocks_'!AA386*'10Stocks'!$D$11)+('10Stocks_'!AD386*'10Stocks'!$D$12) -> 0.0036729946 | AF386: =AF385+(AF385*AE386) -> 141473.47 | AG386: =AG385+(AG385*AE386) -> 103122.06
A387: 55.456589 | B387: =(#REF!-#REF!)/#REF! -> #REF! | C387: =(A387-A386)/A386 -> -0.0015861821 | D387: 120.11 | E387: =(B387-B386)/B386 -> #REF! | F387: =(D387-D386)/D386 -> -0.0080931128 | G387: 45.832623 | H387: =(E387-E386)/E386 -> #REF! | I387: =(G387-G386)/G386 -> 0.0038536092 | J387: 37.451375 | K387: =(H387-H386)/H386 -> #REF! | L387: =(J387-J386)/J386 -> -0.0040090025 | M387: 310.9196 | N387: =(K387-K386)/K386 -> #REF! | O387: =(M387-M386)/M386 -> -0.042398707 | P387: 24.463407 | Q387: =(N387-N386)/N386 -> #REF! | R387: =(P387-P386)/P386 -> -0.013162602 | S387: 27.25 | T387: =(Q387-Q386)/Q386 -> #REF! | U387: =(S387-S386)/S386 -> 0.012634708 | V387: 18.589233 | W387: =(T387-T386)/T386 -> #REF! | X387: =(V387-V386)/V386 -> 0.004199499 | Y387: 25.862899 | Z387: =(W387-W386)/W386 -> #REF! | AA387: =(Y387-Y386)/Y386 -> 0.012439474 | AB387: 74.997064 | AC387: =(Z387-Z386)/Z386 -> #REF! | AD387: =(AB387-AB386)/AB386 -> 0.004464255 | AE387: =(C387*'10Stocks'!$D$3)+(F387*'10Stocks'!$D$4)+('10Stocks_'!I387*'10Stocks'!$D$5)+('10Stocks_'!L387*'10Stocks'!$D$6)+('10Stocks_'!O387*'10Stocks'!$D$7)+('10Stocks_'!R387*'10Stocks'!$D$8)+('10Stocks_'!U387*'10Stocks'!$D$9)+('10Stocks_'!X387*'10Stocks'!$D$10)+('10Stocks_'!AA387*'10Stocks'!$D$11)+('10Stocks_'!AD387*'10Stocks'!$D$12) -> -0.0084241235 | AF387: =AF386+(AF386*AE387) -> 140281.68 | AG387: =AG386+(AG386*AE387) -> 102253.35
A388: 55.65515 | B388: =(#REF!-#REF!)/#REF! -> #REF! | C388: =(A388-A387)/A387 -> 0.0035804763 | D388: 126.88 | E388: =(B388-B387)/B387 -> #REF! | F388: =(D388-D387)/D387 -> 0.056364965 | G388: 46.046267 | H388: =(E388-E387)/E387 -> #REF! | I388: =(G388-G387)/G387 -> 0.0046613959 | J388: 37.338315 | K388: =(H388-H387)/H387 -> #REF! | L388: =(J388-J387)/J387 -> -0.0030188478 | M388: 311.25928 | N388: =(K388-K387)/K387 -> #REF! | O388: =(M388-M387)/M387 -> 0.001092485 | P388: 24.551595 | Q388: =(N388-N387)/N387 -> #REF! | R388: =(P388-P387)/P387 -> 0.0036048944 | S388: 27.620001 | T388: =(Q388-Q387)/Q387 -> #REF! | U388: =(S388-S387)/S387 -> 0.013578018 | V388: 19.318032 | W388: =(T388-T387)/T387 -> #REF! | X388: =(V388-V387)/V387 -> 0.039205437 | Y388: 25.959996 | Z388: =(W388-W387)/W387 -> #REF! | AA388: =(Y388-Y387)/Y387 -> 0.0037542968 | AB388: 75.19004 | AC388: =(Z388-Z387)/Z387 -> #REF! | AD388: =(AB388-AB387)/AB387 -> 0.0025731141 | AE388: =(C388*'10Stocks'!$D$3)+(F388*'10Stocks'!$D$4)+('10Stocks_'!I388*'10Stocks'!$D$5)+('10Stocks_'!L388*'10Stocks'!$D$6)+('10Stocks_'!O388*'10Stocks'!$D$7)+('10Stocks_'!R388*'10Stocks'!$D$8)+('10Stocks_'!U388*'10Stocks'!$D$9)+('10Stocks_'!X388*'10Stocks'!$D$10)+('10Stocks_'!AA388*'10Stocks'!$D$11)+('10Stocks_'!AD388*'10Stocks'!$D$12) -> 0.0022617091 | AF388: =AF387+(AF387*AE388) -> 140598.96 | AG388: =AG387+(AG387*AE388) -> 102484.61
A389: 55.564416 | B389: =(#REF!-#REF!)/#REF! -> #REF! | C389: =(A389-A388)/A388 -> -0.0016302894 | D389: 128.19 | E389: =(B389-B388)/B388 -> #REF! | F389: =(D389-D388)/D388 -> 0.010324756 | G389: 45.248251 | H389: =(E389-E388)/E388 -> #REF! | I389: =(G389-G388)/G388 -> -0.017330743 | J389: 36.462094 | K389: =(H389-H388)/H388 -> #REF! | L389: =(J389-J388)/J388 -> -0.023467074 | M389: 312.66786 | N389: =(K389-K388)/K388 -> #REF! | O389: =(M389-M388)/M388 -> 0.0045254362 | P389: 24.445769 | Q389: =(N389-N388)/N388 -> #REF! | R389: =(P389-P388)/P388 -> -0.0043103513 | S389: 28.23 | T389: =(Q389-Q388)/Q388 -> #REF! | U389: =(S389-S388)/S388 -> 0.022085408 | V389: 19.415205 | W389: =(T389-T388)/T388 -> #REF! | X389: =(V389-V388)/V388 -> 0.0050301708 | Y389: 26.145362 | Z389: =(W389-W388)/W388 -> #REF! | AA389: =(Y389-Y388)/Y388 -> 0.0071404479 | AB389: 74.628659 | AC389: =(Z389-Z388)/Z388 -> #REF! | AD389: =(AB389-AB388)/AB388 -> -0.0074661617 | AE389: =(C389*'10Stocks'!$D$3)+(F389*'10Stocks'!$D$4)+('10Stocks_'!I389*'10Stocks'!$D$5)+('10Stocks_'!L389*'10Stocks'!$D$6)+('10Stocks_'!O389*'10Stocks'!$D$7)+('10Stocks_'!R389*'10Stocks'!$D$8)+('10Stocks_'!U389*'10Stocks'!$D$9)+('10Stocks_'!X389*'10Stocks'!$D$10)+('10Stocks_'!AA389*'10Stocks'!$D$11)+('10Stocks_'!AD389*'10Stocks'!$D$12) -> -0.0053217359 | AF389: =AF388+(AF388*AE389) -> 139850.73 | AG389: =AG388+(AG388*AE389) -> 101939.22
A390: 55.411879 | B390: =(#REF!-#REF!)/#REF! -> #REF! | C390: =(A390-A389)/A389 -> -0.0027452282 | D390: 128.3 | E390: =(B390-B389)/B389 -> #REF! | F390: =(D390-D389)/D389 -> 0.00085810904 | G390: 44.462797 | H390: =(E390-E389)/E389 -> #REF! | I390: =(G390-G389)/G389 -> -0.01735877 | J390: 36.490358 | K390: =(H390-H389)/H389 -> #REF! | L390: =(J390-J389)/J389 -> 0.00077516119 | M390: 314.50603 | N390: =(K390-K389)/K389 -> #REF! | O390: =(M390-M389)/M389 -> 0.0058789732 | P390: 24.692696 | Q390: =(N390-N389)/N389 -> #REF! | R390: =(P390-P389)/P389 -> 0.010101012 | S390: 28.25 | T390: =(Q390-Q389)/Q389 -> #REF! | U390: =(S390-S389)/S389 -> 0.00070846617 | V390: 19.201425 | W390: =(T390-T389)/T389 -> #REF! | X390: =(V390-V389)/V389 -> -0.011010958 | Y390: 26.136535 | Z390: =(W390-W389)/W389 -> #REF! | AA390: =(Y390-Y389)/Y389 -> -0.00033761246 | AB390: 74.330421 | AC390: =(Z390-Z389)/Z389 -> #REF! | AD390: =(AB390-AB389)/AB389 -> -0.0039962932 | AE390: =(C390*'10Stocks'!$D$3)+(F390*'10Stocks'!$D$4)+('10Stocks_'!I390*'10Stocks'!$D$5)+('10Stocks_'!L390*'10Stocks'!$D$6)+('10Stocks_'!O390*'10Stocks'!$D$7)+('10Stocks_'!R390*'10Stocks'!$D$8)+('10Stocks_'!U390*'10Stocks'!$D$9)+('10Stocks_'!X390*'10Stocks'!$D$10)+('10Stocks_'!AA390*'10Stocks'!$D$11)+('10Stocks_'!AD390*'10Stocks'!$D$12) -> 0.0019793285 | AF390: =AF389+(AF389*AE390) -> 140127.54 | AG390: =AG389+(AG389*AE390) -> 102140.99
A391: 55.204114 | B391: =(#REF!-#REF!)/#REF! -> #REF! | C391: =(A391-A390)/A390 -> -0.0037494668 | D391: 127.41 | E391: =(B391-B390)/B390 -> #REF! | F391: =(D391-D390)/D390 -> -0.0069368588 | G391: 44.198887 | H391: =(E391-E390)/E390 -> #REF! | I391: =(G391-G390)/G390 -> -0.005935524 | J391: 36.179443 | K391: =(H391-H390)/H390 -> #REF! | L391: =(J391-J390)/J390 -> -0.00852047 | M391: 312.18335 | N391: =(K391-K390)/K390 -> #REF! | O391: =(M391-M390)/M390 -> -0.0073851653 | P391: 24.913167 | Q391: =(N391-N390)/N390 -> #REF! | R391: =(P391-P390)/P390 -> 0.0089285917 | S391: 22.790001 | T391: =(Q391-Q390)/Q390 -> #REF! | U391: =(S391-S390)/S390 -> -0.1932743 | V391: 19.259728 | W391: =(T391-T390)/T390 -> #REF! | X391: =(V391-V390)/V390 -> 0.0030363892 | Y391: 26.136535 | Z391: =(W391-W390)/W390 -> #REF! | AA391: =(Y391-Y390)/Y390 -> 0 | AB391: 74.453223 | AC391: =(Z391-Z390)/Z390 -> #REF! | AD391: =(AB391-AB390)/AB390 -> 0.0016521096 | AE391: =(C391*'10Stocks'!$D$3)+(F391*'10Stocks'!$D$4)+('10Stocks_'!I391*'10Stocks'!$D$5)+('10Stocks_'!L391*'10Stocks'!$D$6)+('10Stocks_'!O391*'10Stocks'!$D$7)+('10Stocks_'!R391*'10Stocks'!$D$8)+('10Stocks_'!U391*'10Stocks'!$D$9)+('10Stocks_'!X391*'10Stocks'!$D$10)+('10Stocks_'!AA391*'10Stocks'!$D$11)+('10Stocks_'!AD391*'10Stocks'!$D$12) -> -0.036703976 | AF391: =AF390+(AF390*AE391) -> 134984.3 | AG391: =AG390+(AG390*AE391) -> 98392.009
A392: 55.847138 | B392: =(#REF!-#REF!)/#REF! -> #REF! | C392: =(A392-A391)/A391 -> 0.011648117 | D392: 128.85001 | E392: =(B392-B391)/B391 -> #REF! | F392: =(D392-D391)/D391 -> 0.011302111 | G392: 44.48793 | H392: =(E392-E391)/E391 -> #REF! | I392: =(G392-G391)/G391 -> 0.0065395991 | J392: 36.254814 | K392: =(H392-H391)/H391 -> #REF! | L392: =(J392-J391)/J391 -> 0.0020832548 | M392: 313.97656 | N392: =(K392-K391)/K391 -> #REF! | O392: =(M392-M391)/M391 -> 0.005744102 | P392: 24.921986 | Q392: =(N392-N391)/N391 -> #REF! | R392: =(P392-P391)/P391 -> 0.00035398952 | S392: 26.6 | T392: =(Q392-Q391)/Q391 -> #REF! | U392: =(S392-S391)/S391 -> 0.16717854 | V392: 20.114854 | W392: =(T392-T391)/T391 -> #REF! | X392: =(V392-V391)/V391 -> 0.044399692 | Y392: 26.330727 | Z392: =(W392-W391)/W391 -> #REF! | AA392: =(Y392-Y391)/Y391 -> 0.0074299061 | AB392: 75.163726 | AC392: =(Z392-Z391)/Z391 -> #REF! | AD392: =(AB392-AB391)/AB391 -> 0.0095429448 | AE392: =(C392*'10Stocks'!$D$3)+(F392*'10Stocks'!$D$4)+('10Stocks_'!I392*'10Stocks'!$D$5)+('10Stocks_'!L392*'10Stocks'!$D$6)+('10Stocks_'!O392*'10Stocks'!$D$7)+('10Stocks_'!R392*'10Stocks'!$D$8)+('10Stocks_'!U392*'10Stocks'!$D$9)+('10Stocks_'!X392*'10Stocks'!$D$10)+('10Stocks_'!AA392*'10Stocks'!$D$11)+('10Stocks_'!AD392*'10Stocks'!$D$12) -> 0.031821331 | AF392: =AF391+(AF391*AE392) -> 139279.68 | AG392: =AG391+(AG391*AE392) -> 101522.97
A393: 56.427044 | B393: =(#REF!-#REF!)/#REF! -> #REF! | C393: =(A393-A392)/A392 -> 0.010383809 | D393: 126.07 | E393: =(B393-B392)/B392 -> #REF! | F393: =(D393-D392)/D392 -> -0.021575521 | G393: 44.92778 | H393: =(E393-E392)/E392 -> #REF! | I393: =(G393-G392)/G392 -> 0.0098869514 | J393: 36.763589 | K393: =(H393-H392)/H392 -> #REF! | L393: =(J393-J392)/J392 -> 0.014033309 | M393: 316.13941 | N393: =(K393-K392)/K392 -> #REF! | O393: =(M393-M392)/M392 -> 0.0068885619 | P393: 24.895529 | Q393: =(N393-N392)/N392 -> #REF! | R393: =(P393-P392)/P392 -> -0.0010615928 | S393: 26.809999 | T393: =(Q393-Q392)/Q392 -> #REF! | U393: =(S393-S392)/S392 -> 0.0078946992 | V393: 20.950542 | W393: =(T393-T392)/T392 -> #REF! | X393: =(V393-V392)/V392 -> 0.041545815 | Y393: 26.69263 | Z393: =(W393-W392)/W392 -> #REF! | AA393: =(Y393-Y392)/Y392 -> 0.013744512 | AB393: 75.830362 | AC393: =(Z393-Z392)/Z392 -> #REF! | AD393: =(AB393-AB392)/AB392 -> 0.0088691186 | AE393: =(C393*'10Stocks'!$D$3)+(F393*'10Stocks'!$D$4)+('10Stocks_'!I393*'10Stocks'!$D$5)+('10Stocks_'!L393*'10Stocks'!$D$6)+('10Stocks_'!O393*'10Stocks'!$D$7)+('10Stocks_'!R393*'10Stocks'!$D$8)+('10Stocks_'!U393*'10Stocks'!$D$9)+('10Stocks_'!X393*'10Stocks'!$D$10)+('10Stocks_'!AA393*'10Stocks'!$D$11)+('10Stocks_'!AD393*'10Stocks'!$D$12) -> 0.0096371402 | AF393: =AF392+(AF392*AE393) -> 140621.94 | AG393: =AG392+(AG392*AE393) -> 102501.37
A394: 56.248206 | B394: =(#REF!-#REF!)/#REF! -> #REF! | C394: =(A394-A393)/A393 -> -0.0031693668 | D394: 123.62 | E394: =(B394-B393)/B393 -> #REF! | F394: =(D394-D393)/D393 -> -0.019433624 | G394: 44.783259 | H394: =(E394-E393)/E393 -> #REF! | I394: =(G394-G393)/G393 -> -0.0032167403 | J394: 37.1593 | K394: =(H394-H393)/H393 -> #REF! | L394: =(J394-J393)/J393 -> 0.010763666 | M394: 319.46609 | N394: =(K394-K393)/K393 -> #REF! | O394: =(M394-M393)/M393 -> 0.010522826 | P394: 24.798523 | Q394: =(N394-N393)/N393 -> #REF! | R394: =(P394-P393)/P393 -> -0.0038965229 | S394: 26.76 | T394: =(Q394-Q393)/Q393 -> #REF! | U394: =(S394-S393)/S393 -> -0.0018649385 | V394: 21.46556 | W394: =(T394-T393)/T393 -> #REF! | X394: =(V394-V393)/V393 -> 0.024582562 | Y394: 26.613188 | Z394: =(W394-W393)/W393 -> #REF! | AA394: =(Y394-Y393)/Y393 -> -0.0029761773 | AB394: 76.339116 | AC394: =(Z394-Z393)/Z393 -> #REF! | AD394: =(AB394-AB393)/AB393 -> 0.0067091068 | AE394: =(C394*'10Stocks'!$D$3)+(F394*'10Stocks'!$D$4)+('10Stocks_'!I394*'10Stocks'!$D$5)+('10Stocks_'!L394*'10Stocks'!$D$6)+('10Stocks_'!O394*'10Stocks'!$D$7)+('10Stocks_'!R394*'10Stocks'!$D$8)+('10Stocks_'!U394*'10Stocks'!$D$9)+('10Stocks_'!X394*'10Stocks'!$D$10)+('10Stocks_'!AA394*'10Stocks'!$D$11)+('10Stocks_'!AD394*'10Stocks'!$D$12) -> 0.0047740968 | AF394: =AF393+(AF393*AE394) -> 141293.28 | AG394: =AG393+(AG393*AE394) -> 102990.72
